Workbook
Name _Hlk80188971: 'Exclusions '!$B$5
Name _Hlk81725290: 'Exclusions '!$B$1
Name CensusKnown: [1]Code!$C$9
Name Check0: [1]Code!$C$285
Name Check1: [1]Code!$C$286
Name Check10: [1]Code!$C$295
Name Check11: [1]Code!#REF!
Name Check2: [1]Code!$C$287
Name Check3: [1]Code!$C$288
Name Check4: [1]Code!$C$289
Name Check5: [1]Code!$C$290
Name Check6: [1]Code!$C$291
Name Check7: [1]Code!$C$292
Name Check8: [1]Code!$C$293
Name Check9: [1]Code!$C$294
Name CoIns10: [1]Code!$D$66
Name CoIns20: [1]Code!$D$67
Name CoInsDiscount: [1]Code!$D$155
Name CompLoad: [1]Code!$D$159
Name currency: [1]Code!$C$4
Name Data_SOS: [1]Data!$G$3
Name Dental: [1]Code!$D$98
Name DentalLimit: [1]Code!$C$100
Name eff_date: [2]Inputs!$C$17
Name end_date: [2]Inputs!$C$18
Name FlatLoad: [1]Code!$D$153
Name FlatTariff: [1]Code!$C$17
Name Individual: [1]Code!$C$7
Name InNo: [1]Code!$A$166
Name INonly: [1]Code!$C$43
Name INPlan: [1]Code!$C$13
Name InputIntSOS: [1]Code!$D$73
Name IntSOS: [1]Code!$C$74
Name Limit: [1]Code!$C$29
Name Limit_Factor: [1]Code!$D$144
Name LoadIN: [1]Code!$D$150
Name Loadings: [2]Inputs!$H$18
Name LoadInOnly: [1]Code!$D$148
Name LoadOUT: [1]Code!$D$151
Name MarriedGirlsRatio: [1]Code!$C$242
Name MarriedRatio: [1]Code!$C$241
Name Maternity: [1]Code!$D$79
Name NK: [1]Code!$C$182
Name NRP_dental: [1]Code!$C$170
Name NRP_optical: [1]Code!$C$171
Name optical: [1]Code!$D$116
Name OUTNo: [1]Code!$A$168
Name OUTPlan: [1]Code!$C$62
Name Plans_AUH: '[2]Inputs Mapping'!$A$12:$A$14
Name plans_dxb_new: '[2]Inputs Mapping'!$A$4:$A$8
Name SizeLoad: [1]Code!$D$146
Name SOAP10: [1]Code!$D$70
Name SOAP10Discount: [1]Code!$D$157
Name TotalMembers: [1]Code!$C$222
Name version: [1]Code!$D$1

Sheet Premium working
G1: NGI Fee | H1: 0.12 | K1: 45630
D2: NRP increase for the AUH plan Classic - 04 in line with AUH min premium | G2: TPA | H2: 0 | K2: Male Premium - 10% Increased | L2: * Additional Premium for New DHA Benefits | Q2: Dental Premium
G3: Commission | H3: ='Census List'!E28 -> 0.05 | K3: Female Premium - 20% Increased | L3: AED - 173/- For HN Exclusive , Premier & Advantage Network | Q3: TPA | R3: Location | S3: Plan Name | T3: for premium on census | U3: Gross | V3: NRP
H4: =SUM(H1:H3) -> 0.17 | L4: AED - 89/- For HN Standard Plus , Standard & Basic Plus | Q4: Healthnet | R4: Dubai | S4: Prime Plan-1 | T4: =+CONCATENATE(Q4," ",S4," ",R4) -> Healthnet Prime Plan-1 Dubai | U4: =V4/(1-$H$4) -> 506 | V4: 420
A5: TPA | B5: Location | C5: Plans | D5: Age Band | E5: Gender | F5: for premium on Census | G5: Unique ID | H5: Gross Rate | I5: PA | J5: NRP | K5: Revised NRP-04/12/2024 | L5: *Additional Premium | M5: Revised NRP+PA+New DHA benefits | N5: Network | O5: Plans | Q5: Healthnet | R5: Dubai | S5: Prime Plan-2 | T5: =+CONCATENATE(Q5," ",S5," ",R5) -> Healthnet Prime Plan-2 Dubai | U5: =V5/(1-$H$4) -> 422 | V5: 350
A6: Healthnet | B6: Dubai | C6: Prime Plan-1 | D6: 00-17 | E6: Male | F6: =+CONCATENATE(A6," ",C6," ",B6," ",D6," ",E6) -> Healthnet Prime Plan-1 Dubai 00-17 Male | G6: =CONCATENATE(C6," ",D6," ",E6) -> Prime Plan-1 00-17 Male | H6: =ROUND(M6/(1-$H$4),0) -> 6946 | I6: 54.6 | J6: 5034 | K6: =J6+(J6*10%) -> 5537 | L6: 173 | M6: =L6+K6+I6 -> 5765 | N6: HN Exclusive | Q6: Healthnet | R6: Dubai | S6: Classic Plan-1 | T6: =+CONCATENATE(Q6," ",S6," ",R6) -> Healthnet Classic Plan-1 Dubai | U6: =V6/(1-$H$4) -> 422 | V6: 350
A7: Healthnet | B7: Dubai | C7: Prime Plan-1 | D7: 18-35 | E7: Male | F7: =+CONCATENATE(A7," ",C7," ",B7," ",D7," ",E7) -> Healthnet Prime Plan-1 Dubai 18-35 Male | G7: =CONCATENATE(C7," ",D7," ",E7) -> Prime Plan-1 18-35 Male | H7: =ROUND(M7/(1-$H$4),0) -> 8028 | I7: 54.6 | J7: 5850 | K7: =J7+(J7*10%) -> 6435 | L7: 173 | M7: =L7+K7+I7 -> 6663 | N7: HN Exclusive | Q7: Healthnet | R7: Dubai | S7: Classic Plan-2 | T7: =+CONCATENATE(Q7," ",S7," ",R7) -> Healthnet Classic Plan-2 Dubai | U7: =V7/(1-$H$4) -> 361 | V7: 300
A8: Healthnet | B8: Dubai | C8: Prime Plan-1 | D8: 36-45 | E8: Male | F8: =+CONCATENATE(A8," ",C8," ",B8," ",D8," ",E8) -> Healthnet Prime Plan-1 Dubai 36-45 Male | G8: =CONCATENATE(C8," ",D8," ",E8) -> Prime Plan-1 36-45 Male | H8: =ROUND(M8/(1-$H$4),0) -> 9508 | I8: 54.6 | J8: 6967 | K8: =J8+(J8*10%) -> 7664 | L8: 173 | M8: =L8+K8+I8 -> 7892 | N8: HN Exclusive | Q8: Healthnet | R8: Dubai | S8: Classic Plan-3 | T8: =+CONCATENATE(Q8," ",S8," ",R8) -> Healthnet Classic Plan-3 Dubai | U8: =V8/(1-$H$4) -> 361 | V8: 300
A9: Healthnet | B9: Dubai | C9: Prime Plan-1 | D9: 46-55 | E9: Male | F9: =+CONCATENATE(A9," ",C9," ",B9," ",D9," ",E9) -> Healthnet Prime Plan-1 Dubai 46-55 Male | G9: =CONCATENATE(C9," ",D9," ",E9) -> Prime Plan-1 46-55 Male | H9: =ROUND(M9/(1-$H$4),0) -> 16543 | I9: 54.6 | J9: 12275 | K9: =J9+(J9*10%) -> 13503 | L9: 173 | M9: =L9+K9+I9 -> 13731 | N9: HN Exclusive | Q9: Healthnet | R9: Dubai | S9: Classic Plan-4 | T9: =+CONCATENATE(Q9," ",S9," ",R9) -> Healthnet Classic Plan-4 Dubai | U9: =V9/(1-$H$4) -> 361 | V9: 300
A10: Healthnet | B10: Dubai | C10: Prime Plan-1 | D10: 56-59 | E10: Male | F10: =+CONCATENATE(A10," ",C10," ",B10," ",D10," ",E10) -> Healthnet Prime Plan-1 Dubai 56-59 Male | G10: =CONCATENATE(C10," ",D10," ",E10) -> Prime Plan-1 56-59 Male | H10: =ROUND(M10/(1-$H$4),0) -> 20589 | I10: 54.6 | J10: 15328 | K10: =J10+(J10*10%) -> 16861 | L10: 173 | M10: =L10+K10+I10 -> 17089 | N10: HN Exclusive | Q10: Healthnet | R10: Dubai | S10: Classic Plan-1R | T10: =+CONCATENATE(Q10," ",S10," ",R10) -> Healthnet Classic Plan-1R Dubai | U10: =V10/(1-$H$4) -> 422 | V10: 350
A11: Healthnet | B11: Dubai | C11: Prime Plan-1 | D11: 60-65 | E11: Male | F11: =+CONCATENATE(A11," ",C11," ",B11," ",D11," ",E11) -> Healthnet Prime Plan-1 Dubai 60-65 Male | G11: =CONCATENATE(C11," ",D11," ",E11) -> Prime Plan-1 60-65 Male | H11: =ROUND(M11/(1-$H$4),0) -> 29765 | I11: 54.6 | J11: 22252 | K11: =J11+(J11*10%) -> 24477 | L11: 173 | M11: =L11+K11+I11 -> 24705 | N11: HN Exclusive | Q11: Healthnet | R11: Dubai | S11: Classic Plan-2R | T11: =+CONCATENATE(Q11," ",S11," ",R11) -> Healthnet Classic Plan-2R Dubai | U11: =V11/(1-$H$4) -> 361 | V11: 300
A12: Healthnet | B12: Dubai | C12: Prime Plan-1 | D12: 66-70 | E12: Male | F12: =+CONCATENATE(A12," ",C12," ",B12," ",D12," ",E12) -> Healthnet Prime Plan-1 Dubai 66-70 Male | G12: =CONCATENATE(C12," ",D12," ",E12) -> Prime Plan-1 66-70 Male | H12: =ROUND(M12/(1-$H$4),0) -> 46581 | I12: 54.6 | J12: 34940 | K12: =J12+(J12*10%) -> 38434 | L12: 173 | M12: =L12+K12+I12 -> 38662 | N12: HN Exclusive | Q12: Healthnet | R12: Dubai | S12: Classic Plan-3R | T12: =+CONCATENATE(Q12," ",S12," ",R12) -> Healthnet Classic Plan-3R Dubai | U12: =V12/(1-$H$4) -> 361 | V12: 300
A13: Healthnet | B13: Dubai | C13: Prime Plan-1 | D13: 00-17 | E13: Female | F13: =+CONCATENATE(A13," ",C13," ",B13," ",D13," ",E13) -> Healthnet Prime Plan-1 Dubai 00-17 Female | G13: =CONCATENATE(C13," ",D13," ",E13) -> Prime Plan-1 00-17 Female | H13: =ROUND(M13/(1-$H$4),0) -> 7917 | I13: 54.6 | J13: 5286 | K13: =J13+(J13*20%) -> 6343 | L13: 173 | M13: =L13+K13+I13 -> 6571 | N13: HN Exclusive | Q13: Healthnet | R13: Dubai | S13: Classic Plan-4R | T13: =+CONCATENATE(Q13," ",S13," ",R13) -> Healthnet Classic Plan-4R Dubai | U13: =V13/(1-$H$4) -> 361 | V13: 300
A14: Healthnet | B14: Dubai | C14: Prime Plan-1 | D14: 18-35 | E14: Female | F14: =+CONCATENATE(A14," ",C14," ",B14," ",D14," ",E14) -> Healthnet Prime Plan-1 Dubai 18-35 Female | G14: =CONCATENATE(C14," ",D14," ",E14) -> Prime Plan-1 18-35 Female | H14: =ROUND(M14/(1-$H$4),0) -> 9158 | I14: 54.6 | J14: 6144 | K14: =J14+(J14*20%) -> 7373 | L14: 173 | M14: =L14+K14+I14 -> 7601 | N14: HN Exclusive | Q14: Healthnet | R14: Abu Dhabi | S14: Prime Plan-1-AUH | T14: =+CONCATENATE(Q14," ",S14," ",R14) -> Healthnet Prime Plan-1-AUH Abu Dhabi | U14: =V14/(1-$H$4) -> 506 | V14: 420
A15: Healthnet | B15: Dubai | C15: Prime Plan-1 | D15: 36-45 | E15: Female | F15: =+CONCATENATE(A15," ",C15," ",B15," ",D15," ",E15) -> Healthnet Prime Plan-1 Dubai 36-45 Female | G15: =CONCATENATE(C15," ",D15," ",E15) -> Prime Plan-1 36-45 Female | H15: =ROUND(M15/(1-$H$4),0) -> 10852 | I15: 54.6 | J15: 7316 | K15: =J15+(J15*20%) -> 8779 | L15: 173 | M15: =L15+K15+I15 -> 9007 | N15: HN Exclusive | Q15: Healthnet | R15: Abu Dhabi | S15: Prime Plan-2-AUH | T15: =+CONCATENATE(Q15," ",S15," ",R15) -> Healthnet Prime Plan-2-AUH Abu Dhabi | U15: =V15/(1-$H$4) -> 422 | V15: 350
A16: Healthnet | B16: Dubai | C16: Prime Plan-1 | D16: 46-55 | E16: Female | F16: =+CONCATENATE(A16," ",C16," ",B16," ",D16," ",E16) -> Healthnet Prime Plan-1 Dubai 46-55 Female | G16: =CONCATENATE(C16," ",D16," ",E16) -> Prime Plan-1 46-55 Female | H16: =ROUND(M16/(1-$H$4),0) -> 20554 | I16: 54.6 | J16: 14027 | K16: =J16+(J16*20%) -> 16832 | L16: 173 | M16: =L16+K16+I16 -> 17060 | N16: HN Exclusive | Q16: Healthnet | R16: Abu Dhabi | S16: Classic Plan-1-AUH | T16: =+CONCATENATE(Q16," ",S16," ",R16) -> Healthnet Classic Plan-1-AUH Abu Dhabi | U16: =V16/(1-$H$4) -> 422 | V16: 350
A17: Healthnet | B17: Dubai | C17: Prime Plan-1 | D17: 56-59 | E17: Female | F17: =+CONCATENATE(A17," ",C17," ",B17," ",D17," ",E17) -> Healthnet Prime Plan-1 Dubai 56-59 Female | G17: =CONCATENATE(C17," ",D17," ",E17) -> Prime Plan-1 56-59 Female | H17: =ROUND(M17/(1-$H$4),0) -> 25848 | I17: 54.6 | J17: 17688 | K17: =J17+(J17*20%) -> 21226 | L17: 173 | M17: =L17+K17+I17 -> 21454 | N17: HN Exclusive | Q17: Healthnet | R17: Abu Dhabi | S17: Classic Plan-2-AUH | T17: =+CONCATENATE(Q17," ",S17," ",R17) -> Healthnet Classic Plan-2-AUH Abu Dhabi | U17: =V17/(1-$H$4) -> 361 | V17: 300
A18: Healthnet | B18: Dubai | C18: Prime Plan-1 | D18: 60-65 | E18: Female | F18: =+CONCATENATE(A18," ",C18," ",B18," ",D18," ",E18) -> Healthnet Prime Plan-1 Dubai 60-65 Female | G18: =CONCATENATE(C18," ",D18," ",E18) -> Prime Plan-1 60-65 Female | H18: =ROUND(M18/(1-$H$4),0) -> 34054 | I18: 54.6 | J18: 23364 | K18: =J18+(J18*20%) -> 28037 | L18: 173 | M18: =L18+K18+I18 -> 28265 | N18: HN Exclusive | Q18: Healthnet | R18: Abu Dhabi | S18: Classic Plan-3-AUH | T18: =+CONCATENATE(Q18," ",S18," ",R18) -> Healthnet Classic Plan-3-AUH Abu Dhabi | U18: =V18/(1-$H$4) -> 361 | V18: 300
A19: Healthnet | B19: Dubai | C19: Prime Plan-1 | D19: 66-70 | E19: Female | F19: =+CONCATENATE(A19," ",C19," ",B19," ",D19," ",E19) -> Healthnet Prime Plan-1 Dubai 66-70 Female | G19: =CONCATENATE(C19," ",D19," ",E19) -> Prime Plan-1 66-70 Female | H19: =ROUND(M19/(1-$H$4),0) -> 53318 | I19: 54.6 | J19: 36688 | K19: =J19+(J19*20%) -> 44026 | L19: 173 | M19: =L19+K19+I19 -> 44254 | N19: HN Exclusive | Q19: Healthnet | R19: Abu Dhabi | S19: Classic Plan-4-AUH | T19: =+CONCATENATE(Q19," ",S19," ",R19) -> Healthnet Classic Plan-4-AUH Abu Dhabi | U19: =V19/(1-$H$4) -> 361 | V19: 300
A20: Healthnet | B20: Dubai | C20: Prime Plan-2 | D20: 00-17 | E20: Male | F20: =+CONCATENATE(A20," ",C20," ",B20," ",D20," ",E20) -> Healthnet Prime Plan-2 Dubai 00-17 Male | G20: =CONCATENATE(C20," ",D20," ",E20) -> Prime Plan-2 00-17 Male | H20: =ROUND(M20/(1-$H$4),0) -> 5835 | I20: 54.6 | J20: 4195 | K20: =J20+(J20*10%) -> 4615 | L20: 173 | M20: =L20+K20+I20 -> 4843 | N20: HN Premier
A21: Healthnet | B21: Dubai | C21: Prime Plan-2 | D21: 18-35 | E21: Male | F21: =+CONCATENATE(A21," ",C21," ",B21," ",D21," ",E21) -> Healthnet Prime Plan-2 Dubai 18-35 Male | G21: =CONCATENATE(C21," ",D21," ",E21) -> Prime Plan-2 18-35 Male | H21: =ROUND(M21/(1-$H$4),0) -> 6736 | I21: 54.6 | J21: 4875 | K21: =J21+(J21*10%) -> 5363 | L21: 173 | M21: =L21+K21+I21 -> 5591 | N21: HN Premier
A22: Healthnet | B22: Dubai | C22: Prime Plan-2 | D22: 36-45 | E22: Male | F22: =+CONCATENATE(A22," ",C22," ",B22," ",D22," ",E22) -> Healthnet Prime Plan-2 Dubai 36-45 Male | G22: =CONCATENATE(C22," ",D22," ",E22) -> Prime Plan-2 36-45 Male | H22: =ROUND(M22/(1-$H$4),0) -> 7970 | I22: 54.6 | J22: 5806 | K22: =J22+(J22*10%) -> 6387 | L22: 173 | M22: =L22+K22+I22 -> 6615 | N22: HN Premier
A23: Healthnet | B23: Dubai | C23: Prime Plan-2 | D23: 46-55 | E23: Male | F23: =+CONCATENATE(A23," ",C23," ",B23," ",D23," ",E23) -> Healthnet Prime Plan-2 Dubai 46-55 Male | G23: =CONCATENATE(C23," ",D23," ",E23) -> Prime Plan-2 46-55 Male | H23: =ROUND(M23/(1-$H$4),0) -> 13831 | I23: 54.6 | J23: 10229 | K23: =J23+(J23*10%) -> 11252 | L23: 173 | M23: =L23+K23+I23 -> 11480 | N23: HN Premier
A24: Healthnet | B24: Dubai | C24: Prime Plan-2 | D24: 56-59 | E24: Male | F24: =+CONCATENATE(A24," ",C24," ",B24," ",D24," ",E24) -> Healthnet Prime Plan-2 Dubai 56-59 Male | G24: =CONCATENATE(C24," ",D24," ",E24) -> Prime Plan-2 56-59 Male | H24: =ROUND(M24/(1-$H$4),0) -> 17202 | I24: 54.6 | J24: 12773 | K24: =J24+(J24*10%) -> 14050 | L24: 173 | M24: =L24+K24+I24 -> 14278 | N24: HN Premier
A25: Healthnet | B25: Dubai | C25: Prime Plan-2 | D25: 60-65 | E25: Male | F25: =+CONCATENATE(A25," ",C25," ",B25," ",D25," ",E25) -> Healthnet Prime Plan-2 Dubai 60-65 Male | G25: =CONCATENATE(C25," ",D25," ",E25) -> Prime Plan-2 60-65 Male | H25: =ROUND(M25/(1-$H$4),0) -> 24849 | I25: 54.6 | J25: 18543 | K25: =J25+(J25*10%) -> 20397 | L25: 173 | M25: =L25+K25+I25 -> 20625 | N25: HN Premier
A26: Healthnet | B26: Dubai | C26: Prime Plan-2 | D26: 66-70 | E26: Male | F26: =+CONCATENATE(A26," ",C26," ",B26," ",D26," ",E26) -> Healthnet Prime Plan-2 Dubai 66-70 Male | G26: =CONCATENATE(C26," ",D26," ",E26) -> Prime Plan-2 66-70 Male | H26: =ROUND(M26/(1-$H$4),0) -> 38864 | I26: 54.6 | J26: 29117 | K26: =J26+(J26*10%) -> 32029 | L26: 173 | M26: =L26+K26+I26 -> 32257 | N26: HN Premier
A27: Healthnet | B27: Dubai | C27: Prime Plan-2 | D27: 00-17 | E27: Female | F27: =+CONCATENATE(A27," ",C27," ",B27," ",D27," ",E27) -> Healthnet Prime Plan-2 Dubai 00-17 Female | G27: =CONCATENATE(C27," ",D27," ",E27) -> Prime Plan-2 00-17 Female | H27: =ROUND(M27/(1-$H$4),0) -> 6643 | I27: 54.6 | J27: 4405 | K27: =J27+(J27*20%) -> 5286 | L27: 173 | M27: =L27+K27+I27 -> 5514 | N27: HN Premier
A28: Healthnet | B28: Dubai | C28: Prime Plan-2 | D28: 18-35 | E28: Female | F28: =+CONCATENATE(A28," ",C28," ",B28," ",D28," ",E28) -> Healthnet Prime Plan-2 Dubai 18-35 Female | G28: =CONCATENATE(C28," ",D28," ",E28) -> Prime Plan-2 18-35 Female | H28: =ROUND(M28/(1-$H$4),0) -> 7677 | I28: 54.6 | J28: 5120 | K28: =J28+(J28*20%) -> 6144 | L28: 173 | M28: =L28+K28+I28 -> 6372 | N28: HN Premier
A29: Healthnet | B29: Dubai | C29: Prime Plan-2 | D29: 36-45 | E29: Female | F29: =+CONCATENATE(A29," ",C29," ",B29," ",D29," ",E29) -> Healthnet Prime Plan-2 Dubai 36-45 Female | G29: =CONCATENATE(C29," ",D29," ",E29) -> Prime Plan-2 36-45 Female | H29: =ROUND(M29/(1-$H$4),0) -> 9089 | I29: 54.6 | J29: 6097 | K29: =J29+(J29*20%) -> 7316 | L29: 173 | M29: =L29+K29+I29 -> 7544 | N29: HN Premier
A30: Healthnet | B30: Dubai | C30: Prime Plan-2 | D30: 46-55 | E30: Female | F30: =+CONCATENATE(A30," ",C30," ",B30," ",D30," ",E30) -> Healthnet Prime Plan-2 Dubai 46-55 Female | G30: =CONCATENATE(C30," ",D30," ",E30) -> Prime Plan-2 46-55 Female | H30: =ROUND(M30/(1-$H$4),0) -> 17175 | I30: 54.6 | J30: 11689 | K30: =J30+(J30*20%) -> 14027 | L30: 173 | M30: =L30+K30+I30 -> 14255 | N30: HN Premier | X30: Age Band | Y30: Gender | Z30: Network | AA30: NRP - R | AB30: NRP - Classic - Open
A31: Healthnet | B31: Dubai | C31: Prime Plan-2 | D31: 56-59 | E31: Female | F31: =+CONCATENATE(A31," ",C31," ",B31," ",D31," ",E31) -> Healthnet Prime Plan-2 Dubai 56-59 Female | G31: =CONCATENATE(C31," ",D31," ",E31) -> Prime Plan-2 56-59 Female | H31: =ROUND(M31/(1-$H$4),0) -> 21586 | I31: 54.6 | J31: 14740 | K31: =J31+(J31*20%) -> 17688 | L31: 173 | M31: =L31+K31+I31 -> 17916 | N31: HN Premier | X31: 00-17 | Y31: Male | Z31: HN Exclusive | AA31: =AA45+(AA45*20%) -> 4840 | AB31: =AA31+(AA31*$AC$34) -> 4840 | AC31: 0.15
A32: Healthnet | B32: Dubai | C32: Prime Plan-2 | D32: 60-65 | E32: Female | F32: =+CONCATENATE(A32," ",C32," ",B32," ",D32," ",E32) -> Healthnet Prime Plan-2 Dubai 60-65 Female | G32: =CONCATENATE(C32," ",D32," ",E32) -> Prime Plan-2 60-65 Female | H32: =ROUND(M32/(1-$H$4),0) -> 28424 | I32: 54.6 | J32: 19470 | K32: =J32+(J32*20%) -> 23364 | L32: 173 | M32: =L32+K32+I32 -> 23592 | N32: HN Premier | X32: 18-35 | Y32: Male | AA32: =AA46+(AA46*20%) -> 5549 | AB32: =AA32+(AA32*$AC$34) -> 5549
A33: Healthnet | B33: Dubai | C33: Prime Plan-2 | D33: 66-70 | E33: Female | F33: =+CONCATENATE(A33," ",C33," ",B33," ",D33," ",E33) -> Healthnet Prime Plan-2 Dubai 66-70 Female | G33: =CONCATENATE(C33," ",D33," ",E33) -> Prime Plan-2 66-70 Female | H33: =ROUND(M33/(1-$H$4),0) -> 44477 | I33: 54.6 | J33: 30573 | K33: =J33+(J33*20%) -> 36688 | L33: 173 | M33: =L33+K33+I33 -> 36916 | N33: HN Premier | X33: 36-45 | Y33: Male | AA33: =AA47+(AA47*20%) -> 6521 | AB33: =AA33+(AA33*$AC$34) -> 6521
A34: Healthnet | B34: Dubai | C34: Classic Plan-1 | D34: 00-17 | E34: Male | F34: =+CONCATENATE(A34," ",C34," ",B34," ",D34," ",E34) -> Healthnet Classic Plan-1 Dubai 00-17 Male | G34: =CONCATENATE(C34," ",D34," ",E34) -> Classic Plan-1 00-17 Male | H34: =ROUND(M34/(1-$H$4),0) -> 4877 | I34: 54.6 | J34: 3473 | K34: =J34+(J34*10%) -> 3820 | L34: 173 | M34: =L34+K34+I34 -> 4048 | N34: HN Advantage | X34: 46-55 | Y34: Male | AA34: =AA48+(AA48*20%) -> 11136 | AB34: =AA34+(AA34*$AC$34) -> 11136
A35: Healthnet | B35: Dubai | C35: Classic Plan-1 | D35: 18-35 | E35: Male | F35: =+CONCATENATE(A35," ",C35," ",B35," ",D35," ",E35) -> Healthnet Classic Plan-1 Dubai 18-35 Male | G35: =CONCATENATE(C35," ",D35," ",E35) -> Classic Plan-1 18-35 Male | H35: =ROUND(M35/(1-$H$4),0) -> 5623 | I35: 54.6 | J35: 4035 | K35: =J35+(J35*10%) -> 4439 | L35: 173 | M35: =L35+K35+I35 -> 4667 | N35: HN Advantage | X35: 56-59 | Y35: Male | AA35: =AA49+(AA49*20%) -> 13790 | AB35: =AA35+(AA35*$AC$34) -> 13790
A36: Healthnet | B36: Dubai | C36: Classic Plan-1 | D36: 36-45 | E36: Male | F36: =+CONCATENATE(A36," ",C36," ",B36," ",D36," ",E36) -> Healthnet Classic Plan-1 Dubai 36-45 Male | G36: =CONCATENATE(C36," ",D36," ",E36) -> Classic Plan-1 36-45 Male | H36: =ROUND(M36/(1-$H$4),0) -> 6646 | I36: 54.6 | J36: 4807 | K36: =J36+(J36*10%) -> 5288 | L36: 173 | M36: =L36+K36+I36 -> 5516 | N36: HN Advantage | X36: 60 - 65 | Y36: Male | AA36: =AA50+(AA50*20%) -> 19811 | AB36: =AA36+(AA36*$AC$34) -> 19811
A37: Healthnet | B37: Dubai | C37: Classic Plan-1 | D37: 46-55 | E37: Male | F37: =+CONCATENATE(A37," ",C37," ",B37," ",D37," ",E37) -> Healthnet Classic Plan-1 Dubai 46-55 Male | G37: =CONCATENATE(C37," ",D37," ",E37) -> Classic Plan-1 46-55 Male | H37: =ROUND(M37/(1-$H$4),0) -> 11498 | I37: 54.6 | J37: 8468 | K37: =J37+(J37*10%) -> 9315 | L37: 173 | M37: =L37+K37+I37 -> 9543 | N37: HN Advantage | X37: 66 and above | Y37: Male | AA37: =AA51+(AA51*20%) -> 30845 | AB37: =AA37+(AA37*$AC$34) -> 30845
A38: Healthnet | B38: Dubai | C38: Classic Plan-1 | D38: 56-59 | E38: Male | F38: =+CONCATENATE(A38," ",C38," ",B38," ",D38," ",E38) -> Healthnet Classic Plan-1 Dubai 56-59 Male | G38: =CONCATENATE(C38," ",D38," ",E38) -> Classic Plan-1 56-59 Male | H38: =ROUND(M38/(1-$H$4),0) -> 14288 | I38: 54.6 | J38: 10574 | K38: =J38+(J38*10%) -> 11631 | L38: 173 | M38: =L38+K38+I38 -> 11859 | N38: HN Advantage | X38: 00-17 | Y38: Female | AA38: =AA52+(AA52*20%) -> 5081 | AB38: =AA38+(AA38*$AC$34) -> 5081
A39: Healthnet | B39: Dubai | C39: Classic Plan-1 | D39: 60-65 | E39: Male | F39: =+CONCATENATE(A39," ",C39," ",B39," ",D39," ",E39) -> Healthnet Classic Plan-1 Dubai 60-65 Male | G39: =CONCATENATE(C39," ",D39," ",E39) -> Classic Plan-1 60-65 Male | H39: =ROUND(M39/(1-$H$4),0) -> 20618 | I39: 54.6 | J39: 15350 | K39: =J39+(J39*10%) -> 16885 | L39: 173 | M39: =L39+K39+I39 -> 17113 | N39: HN Advantage | X39: 18-35 | Y39: Female | AA39: =AA53+(AA53*20%) -> 8202 | AB39: =AA39+(AA39*$AC$34) -> 8202
A40: Healthnet | B40: Dubai | C40: Classic Plan-1 | D40: 66-70 | E40: Male | F40: =+CONCATENATE(A40," ",C40," ",B40," ",D40," ",E40) -> Healthnet Classic Plan-1 Dubai 66-70 Male | G40: =CONCATENATE(C40," ",D40," ",E40) -> Classic Plan-1 66-70 Male | H40: =ROUND(M40/(1-$H$4),0) -> 32219 | I40: 54.6 | J40: 24104 | K40: =J40+(J40*10%) -> 26514 | L40: 173 | M40: =L40+K40+I40 -> 26742 | N40: HN Advantage | X40: 36-45 | Y40: Female | AA40: =AA54+(AA54*20%) -> 9223 | AB40: =AA40+(AA40*$AC$34) -> 9223
...

Sheet Census List
M1: Head Office
B2: Prime Plan-1 | M2: Ajman
B3: Prime Plan-2 | M3: Bur Dubai | P3: Prime Plan-1-AUH | Q3: without | R3: 48422 | T3: Prime Plan-1-AUH | U3: with Dental | V3: 48426
B4: Classic Plan-1 | M4: Al Barsha | P4: Prime Plan-2-AUH | Q4: without | R4: 48455 | T4: Prime Plan-2-AUH | U4: with Dental | V4: 48453
B5: Classic Plan-2 | I5: Head Office | M5: Sharjah | P5: Classic Plan-1-AUH | Q5: without | R5: 48457 | T5: Classic Plan-1-AUH | U5: with Dental | V5: 48460
B6: Classic Plan-3 | G6: BDE | I6: Ajman | M6: SZK | P6: Classic Plan-2-AUH | Q6: without | R6: 48461 | T6: Classic Plan-2-AUH | U6: with Dental | V6: 48465
B7: Classic Plan-4 | D7: Married | G7: Broker | I7: Bur Dubai | M7: Abu Dhabi | P7: Classic Plan-3-AUH | Q7: without | R7: 48468 | T7: Classic Plan-3-AUH | U7: with Dental | V7: 48468
B8: Classic Plan-1R | D8: Single | I8: Al Barsha | M8: DIP | P8: Classic Plan-4-AUH | Q8: without | R8: 48469 | T8: Classic Plan-4-AUH | U8: with Dental | V8: 48471
B9: Classic Plan-2R | G9: Yes | I9: Sharjah | L9: Dubai
B10: Classic Plan-3R | D10: Male | G10: No | I10: SZK | L10: Abu Dhabi | O10: DOH # | P10: =IF(D35="Dubai","",IF(D36="Yes",VLOOKUP(D34,T3:V8,3,0),VLOOKUP(D34,P3:R8,3,0)))
B11: Classic Plan-4R | D11: Female | I11: Abu Dhabi
B12: Prime Plan-1-AUH | I12: DIP | P12: =_xlfn.CONCAT(O10," ",P10) -> DOH #
B13: Prime Plan-2-AUH | D13: Principal
B14: Classic Plan-1-AUH | D14: Spouse | F14: Healthnet
B15: Classic Plan-2-AUH | D15: Child | F15: Healthnet
B16: Classic Plan-3-AUH
B17: Classic Plan-4-AUH | D17: Enhanced | E17: Yes
D18: Basic | E18: No
D20: Dubai | L20: =CONCATENATE(J33," ",J35,"- ",J36) -> Head Office -
D21: NE
D22: AUH | L22: Fixed
L23: Percentage
N27: Amount | O27: %
E28: 0.05 | F28: =IF(E28>15%,"Maximum Commission is 15%"," ") | I28: Additional Loading on Maternity (On NRP) | M28: Fixed
O30: Tool Version 2025/3
A32: Policy Holder Name : | H32: Source Type | J32: BDE
A33: TPA : | D33: Healthnet | H33: Branch | J33: Head Office
A34: Plan Name : | D34: Classic Plan-2 | H34: Source Name
A35: Location : | D35: Dubai | H35: BDE Pin No
A36: Dental Benefits : | D36: Enhanced | H36: Quote No
A37: Visa Location : | D37: AUH | J37: Underwriting Comments
A38: Professional : | D38: Others | J38: =VLOOKUP(D38,'TOB IN PUT'!E38:F46,2,0) -> Please Proceed
A40: Census Information
A41: Name | D41: Gender | E41: Date of Birth | F41: Marital Status | G41: Dependency | H41: Nationality | I41: Age | J41: Age Band | K41: Premium | L41: Addional Loading | M41: Final Premium | N41: Dental | O41: Maternity | P41: Total Premium | R41: Addional Loading
A42: HUSSEIN ALI CHABANI | D42: Male | E42: 27003 | F42: Married | G42: Principal | H42: SYRIA | I42: =IFERROR((IF(E42=0,"",(ROUND((TODAY()-E42)/365.25,0)))),"") -> 52 | J42: =IFERROR(IF((CONCATENATE($D$33,"&",$D$35))='Age Band'!$A$1,VLOOKUP('Census List'!I42,'Age Band'!$A:$B,2,0),IF((CONCATENATE($D$33,"&",$D$35))='Age Band'!$D$1,VLOOKUP('Census List'!I42,'Age Band'!$D:$E,2,0),(IF($D$35='Age Band'!$G$1,VLOOKUP('Census List'!I42,'Age Band'!$G:$H,2,0),0)))),"") -> 46-55 | K42: =IFERROR((VLOOKUP((CONCATENATE($D$33," ",$D$34," ",$D$35," ",J42," ",D42)),'Premium working'!$F$5:$H$227,3,0)),"") -> 8461 | L42: 0 | M42: =IFERROR(K42+(K42*R42),"") -> 8461 | N42: =IFERROR(IF(E42<>"",(IF($D$36="Enhanced",(VLOOKUP((CONCATENATE($D$33," ",$D$34," ",$D$35)),'Premium working'!$T$4:$U$19,2,0)),0)),""),"") -> 361 | O42: =IFERROR(IF($D$35="Dubai",IF((COUNTIFS(D42,"Female",F42,"Married",I42,">=18",I42,"<=45"))=1,VLOOKUP((CONCATENATE($D$33," ",$D$34," ",$D$35," Maternity")),'Premium working'!$F:$H,3,0),0),IF($D$35="Abu Dhabi",IF((COUNTIFS(D42,"Female",F42,"Married",I42,">=18",I42,"<=50"))=1,VLOOKUP((CONCATENATE($D$33," ",$D$34," ",$D$35," Maternity")),'Premium working'!$F:$H,3,0),),"Not Applicable")),"") -> 0 | P42: =IFERROR(M42+N42+O42,"") -> 8822 | R42: 0
A43: KINDA AL ASSAD | D43: Female | E43: 28911 | F43: Married | G43: Spouse | H43: SYRIA | I43: =IFERROR((IF(E43=0,"",(ROUND((TODAY()-E43)/365.25,0)))),"") -> 47 | J43: =IFERROR(IF((CONCATENATE($D$33,"&",$D$35))='Age Band'!$A$1,VLOOKUP('Census List'!I43,'Age Band'!$A:$B,2,0),IF((CONCATENATE($D$33,"&",$D$35))='Age Band'!$D$1,VLOOKUP('Census List'!I43,'Age Band'!$D:$E,2,0),(IF($D$35='Age Band'!$G$1,VLOOKUP('Census List'!I43,'Age Band'!$G:$H,2,0),0)))),"") -> 46-55 | K43: =IFERROR((VLOOKUP((CONCATENATE($D$33," ",$D$34," ",$D$35," ",J43," ",D43)),'Premium working'!$F$5:$H$227,3,0)),"") -> 10835 | L43: 0 | M43: =IFERROR(K43+(K43*R43),"") -> 10835 | N43: =IFERROR(IF(E43<>"",(IF($D$36="Enhanced",(VLOOKUP((CONCATENATE($D$33," ",$D$34," ",$D$35)),'Premium working'!$T$4:$U$19,2,0)),0)),""),"") -> 361 | O43: =IFERROR(IF($D$35="Dubai",IF((COUNTIFS(D43,"Female",F43,"Married",I43,">=18",I43,"<=45"))=1,VLOOKUP((CONCATENATE($D$33," ",$D$34," ",$D$35," Maternity")),'Premium working'!$F:$H,3,0),0),IF($D$35="Abu Dhabi",IF((COUNTIFS(D43,"Female",F43,"Married",I43,">=18",I43,"<=50"))=1,VLOOKUP((CONCATENATE($D$33," ",$D$34," ",$D$35," Maternity")),'Premium working'!$F:$H,3,0),),"Not Applicable")),"") -> 0 | P43: =IFERROR(M43+N43+O43,"") -> 11196 | R43: 0
A44: LAYAL CHABANI | D44: Female | E44: 40409 | F44: Single | G44: Child | H44: SYRIA | I44: =IFERROR((IF(E44=0,"",(ROUND((TODAY()-E44)/365.25,0)))),"") -> 15 | J44: =IFERROR(IF((CONCATENATE($D$33,"&",$D$35))='Age Band'!$A$1,VLOOKUP('Census List'!I44,'Age Band'!$A:$B,2,0),IF((CONCATENATE($D$33,"&",$D$35))='Age Band'!$D$1,VLOOKUP('Census List'!I44,'Age Band'!$D:$E,2,0),(IF($D$35='Age Band'!$G$1,VLOOKUP('Census List'!I44,'Age Band'!$G:$H,2,0),0)))),"") -> 00-17 | K44: =IFERROR((VLOOKUP((CONCATENATE($D$33," ",$D$34," ",$D$35," ",J44," ",D44)),'Premium working'!$F$5:$H$227,3,0)),"") -> 5128 | L44: 0 | M44: =IFERROR(K44+(K44*R44),"") -> 5128 | N44: =IFERROR(IF(E44<>"",(IF($D$36="Enhanced",(VLOOKUP((CONCATENATE($D$33," ",$D$34," ",$D$35)),'Premium working'!$T$4:$U$19,2,0)),0)),""),"") -> 361 | O44: =IFERROR(IF($D$35="Dubai",IF((COUNTIFS(D44,"Female",F44,"Married",I44,">=18",I44,"<=45"))=1,VLOOKUP((CONCATENATE($D$33," ",$D$34," ",$D$35," Maternity")),'Premium working'!$F:$H,3,0),0),IF($D$35="Abu Dhabi",IF((COUNTIFS(D44,"Female",F44,"Married",I44,">=18",I44,"<=50"))=1,VLOOKUP((CONCATENATE($D$33," ",$D$34," ",$D$35," Maternity")),'Premium working'!$F:$H,3,0),),"Not Applicable")),"") -> 0 | P44: =IFERROR(M44+N44+O44,"") -> 5489 | R44: 0
A45: ALY CHABANI | D45: Male | E45: 39320 | F45: Single | G45: Child | H45: SYRIA | I45: =IFERROR((IF(E45=0,"",(ROUND((TODAY()-E45)/365.25,0)))),"") -> 18 | J45: =IFERROR(IF((CONCATENATE($D$33,"&",$D$35))='Age Band'!$A$1,VLOOKUP('Census List'!I45,'Age Band'!$A:$B,2,0),IF((CONCATENATE($D$33,"&",$D$35))='Age Band'!$D$1,VLOOKUP('Census List'!I45,'Age Band'!$D:$E,2,0),(IF($D$35='Age Band'!$G$1,VLOOKUP('Census List'!I45,'Age Band'!$G:$H,2,0),0)))),"") -> 18-35 | K45: =IFERROR((VLOOKUP((CONCATENATE($D$33," ",$D$34," ",$D$35," ",J45," ",D45)),'Premium working'!$F$5:$H$227,3,0)),"") -> 4439 | L45: 0 | M45: =IFERROR(K45+(K45*R45),"") -> 4439 | N45: =IFERROR(IF(E45<>"",(IF($D$36="Enhanced",(VLOOKUP((CONCATENATE($D$33," ",$D$34," ",$D$35)),'Premium working'!$T$4:$U$19,2,0)),0)),""),"") -> 361 | O45: =IFERROR(IF($D$35="Dubai",IF((COUNTIFS(D45,"Female",F45,"Married",I45,">=18",I45,"<=45"))=1,VLOOKUP((CONCATENATE($D$33," ",$D$34," ",$D$35," Maternity")),'Premium working'!$F:$H,3,0),0),IF($D$35="Abu Dhabi",IF((COUNTIFS(D45,"Female",F45,"Married",I45,">=18",I45,"<=50"))=1,VLOOKUP((CONCATENATE($D$33," ",$D$34," ",$D$35," Maternity")),'Premium working'!$F:$H,3,0),),"Not Applicable")),"") -> 0 | P45: =IFERROR(M45+N45+O45,"") -> 4800 | R45: 0
I46: =IFERROR((IF(E46=0,"",(ROUND((TODAY()-E46)/365.25,0)))),"") | J46: =IFERROR(IF((CONCATENATE($D$33,"&",$D$35))='Age Band'!$A$1,VLOOKUP('Census List'!I46,'Age Band'!$A:$B,2,0),IF((CONCATENATE($D$33,"&",$D$35))='Age Band'!$D$1,VLOOKUP('Census List'!I46,'Age Band'!$D:$E,2,0),(IF($D$35='Age Band'!$G$1,VLOOKUP('Census List'!I46,'Age Band'!$G:$H,2,0),0)))),"") | K46: =IFERROR((VLOOKUP((CONCATENATE($D$33," ",$D$34," ",$D$35," ",J46," ",D46)),'Premium working'!$F$5:$H$227,3,0)),"") | M46: =IFERROR(K46+(K46*R46),"") | N46: =IFERROR(IF(E46<>"",(IF($D$36="Enhanced",(VLOOKUP((CONCATENATE($D$33," ",$D$34," ",$D$35)),'Premium working'!$T$4:$U$19,2,0)),0)),""),"") | O46: =IFERROR(IF($D$35="Dubai",IF((COUNTIFS(D46,"Female",F46,"Married",I46,">=18",I46,"<=45"))=1,VLOOKUP((CONCATENATE($D$33," ",$D$34," ",$D$35," Maternity")),'Premium working'!$F:$H,3,0),0),IF($D$35="Abu Dhabi",IF((COUNTIFS(D46,"Female",F46,"Married",I46,">=18",I46,"<=50"))=1,VLOOKUP((CONCATENATE($D$33," ",$D$34," ",$D$35," Maternity")),'Premium working'!$F:$H,3,0),),"Not Applicable")),"") -> 0 | P46: =IFERROR(M46+N46+O46,"") | R46: 0
I47: =IFERROR((IF(E47=0,"",(ROUND((TODAY()-E47)/365.25,0)))),"") | J47: =IFERROR(IF((CONCATENATE($D$33,"&",$D$35))='Age Band'!$A$1,VLOOKUP('Census List'!I47,'Age Band'!$A:$B,2,0),IF((CONCATENATE($D$33,"&",$D$35))='Age Band'!$D$1,VLOOKUP('Census List'!I47,'Age Band'!$D:$E,2,0),(IF($D$35='Age Band'!$G$1,VLOOKUP('Census List'!I47,'Age Band'!$G:$H,2,0),0)))),"") | K47: =IFERROR((VLOOKUP((CONCATENATE($D$33," ",$D$34," ",$D$35," ",J47," ",D47)),'Premium working'!$F$5:$H$227,3,0)),"") | M47: =IFERROR(K47+(K47*R47),"") | N47: =IFERROR(IF(E47<>"",(IF($D$36="Enhanced",(VLOOKUP((CONCATENATE($D$33," ",$D$34," ",$D$35)),'Premium working'!$T$4:$U$19,2,0)),0)),""),"") | O47: =IFERROR(IF($D$35="Dubai",IF((COUNTIFS(D47,"Female",F47,"Married",I47,">=18",I47,"<=45"))=1,VLOOKUP((CONCATENATE($D$33," ",$D$34," ",$D$35," Maternity")),'Premium working'!$F:$H,3,0),0),IF($D$35="Abu Dhabi",IF((COUNTIFS(D47,"Female",F47,"Married",I47,">=18",I47,"<=50"))=1,VLOOKUP((CONCATENATE($D$33," ",$D$34," ",$D$35," Maternity")),'Premium working'!$F:$H,3,0),),"Not Applicable")),"") -> 0 | P47: =IFERROR(M47+N47+O47,"") | R47: 0
...

Sheet Age Band
A1: Healthnet&Dubai | D1: Nextcare&Dubai | G1: Abu Dhabi
A2: No | B2: bracket | D2: No | E2: bracket | G2: No | H2: bracket
A3: 0 | B3: 00-17 | D3: 0 | E3: 00-15 | G3: 0 | H3: 00-17
A4: 1 | B4: 00-17 | D4: 1 | E4: 00-15 | G4: 1 | H4: 00-17
A5: 2 | B5: 00-17 | D5: 2 | E5: 00-15 | G5: 2 | H5: 00-17
A6: 3 | B6: 00-17 | D6: 3 | E6: 00-15 | G6: 3 | H6: 00-17
A7: 4 | B7: 00-17 | D7: 4 | E7: 00-15 | G7: 4 | H7: 00-17
A8: 5 | B8: 00-17 | D8: 5 | E8: 00-15 | G8: 5 | H8: 00-17
A9: 6 | B9: 00-17 | D9: 6 | E9: 00-15 | G9: 6 | H9: 00-17
A10: 7 | B10: 00-17 | D10: 7 | E10: 00-15 | G10: 7 | H10: 00-17
A11: 8 | B11: 00-17 | D11: 8 | E11: 00-15 | G11: 8 | H11: 00-17
A12: 9 | B12: 00-17 | D12: 9 | E12: 00-15 | G12: 9 | H12: 00-17
A13: 10 | B13: 00-17 | D13: 10 | E13: 00-15 | G13: 10 | H13: 00-17
A14: 11 | B14: 00-17 | D14: 11 | E14: 00-15 | G14: 11 | H14: 00-17
... A69: 66 | B69: 66-70 | D69: 66 | E69: 66-69 | G69: 66 | H69: 60-69
A70: =A69+1 -> 67 | B70: 66-70 | D70: =D69+1 -> 67 | E70: 66-69 | G70: =G69+1 -> 67 | H70: 60-69
A71: =A70+1 -> 68 | B71: 66-70 | D71: =D70+1 -> 68 | E71: 66-69 | G71: =G70+1 -> 68 | H71: 60-69
A72: =A71+1 -> 69 | B72: 66-70 | D72: =D71+1 -> 69 | E72: 66-69 | G72: =G71+1 -> 69 | H72: 60-69
A73: =A72+1 -> 70 | B73: 66-70 | D73: =D72+1 -> 70 | E73: 70-75 | G73: =G72+1 -> 70 | H73: 70-75
A74: =A73+1 -> 71 | B74: Refer to HO | D74: =D73+1 -> 71 | E74: 70-75 | G74: =G73+1 -> 71 | H74: 70-75
A75: =A74+1 -> 72 | B75: Refer to HO | D75: =D74+1 -> 72 | E75: 70-75 | G75: =G74+1 -> 72 | H75: 70-75
A76: =A75+1 -> 73 | B76: Refer to HO | D76: =D75+1 -> 73 | E76: 70-75 | G76: =G75+1 -> 73 | H76: 70-75
A77: =A76+1 -> 74 | B77: Refer to HO | D77: =D76+1 -> 74 | E77: 70-75 | G77: =G76+1 -> 74 | H77: 70-75
A78: =A77+1 -> 75 | B78: Refer to HO | D78: =D77+1 -> 75 | E78: 70-75 | G78: =G77+1 -> 75 | H78: 70-75
A79: =A78+1 -> 76 | B79: Refer to HO | D79: =D78+1 -> 76 | E79: 76-80 | G79: =G78+1 -> 76 | H79: 76-80
A80: =A79+1 -> 77 | B80: Refer to HO | D80: =D79+1 -> 77 | E80: 76-80 | G80: =G79+1 -> 77 | H80: 76-80
A81: =A80+1 -> 78 | B81: Refer to HO | D81: =D80+1 -> 78 | E81: 76-80 | G81: =G80+1 -> 78 | H81: 76-80
... A103: =A102+1 -> 100 | B103: Refer to HO | D103: =D102+1 -> 100 | E103: Refer to HO | G103: =G102+1 -> 100 | H103: Refer to HO

Sheet TOB 
A2: Date | B2: =TODAY() -> 46024 | G2: Ref Number : | H2: ='Census List'!L20 -> Head Office -
A3: Policy Holder Name | B3: ='Census List'!D32 -> 0
A5: Medical Insurance Program – | F5: ='Census List'!D33 -> Healthnet
A6: Dear Sir, National General Insurance Company (NGI) is pleased to welcome you to enroll in a distinctively designed program for you. NGI is a leading composite insurer in UAE, recognized as a fully accredited National Insurer, publicly listed, and rated “A-(Excellent)” by AM Best. The Health Plans for are tailored with comprehensive range of benefits, compliant to DHA and DOH-AUH, and offer highest levels of service and care to the insured members. We are pleased to offer you our proposal and hope that you will find the quoted terms competitive. Please do not hesitate to contact us for further assistance or any clarification that you may need on the product and services. On behalf of Medical Department - National General Insurance (NGI)
A7: Plan Name | D7: ='Census List'!D34 -> Classic Plan-2 | H7: =IF('Census List'!D35="Dubai","",'Census List'!P12)
A8: Table of Benefits
A9: Maximum Benefit Per Year | D9: =VLOOKUP($D$7,'TOB IN PUT'!A2:S17,3,0) -> AED 250,000 | J9: =D22 -> Covered on Reimbursement up to AED 250 per night and a maximum of 10 nights. The Cash Indemnity claim must be submitted within 15 days after discharge from the hospital with a proof of hospitalization including a discharge summary.
A10: Area of Coverage | D10: =VLOOKUP($D$7,'TOB IN PUT'!$A$2:$S$17,4,0) -> Worldwide Excluding USA and Canada
A11: Provider Network | D11: =VLOOKUP($D$7,'TOB IN PUT'!$A$2:$S$17,5,0) -> HN Standard Plus (Additional 10% Co-pay applicable on all OP Services excluding Pharmacy at NMC Royal Hosp. Sharjah) | J11: =D11 -> HN Standard Plus (Additional 10% Co-pay applicable on all OP Services excluding Pharmacy at NMC Royal Hosp. Sharjah)
A12: Pre-existing & Chronic Conditions Subject to Medical Application Form (MAF) | B12: Coverage | D12: =IF('Census List'!D35="Dubai","Covered up to a limit of AED 150,000 per member per year","Covered up to a limit of AED 250,000 per member per year") -> Covered up to a limit of AED 150,000 per member per year
B13: Note | D13: No waiting period applies if evidence of continuity of coverage is provided; otherwise a waiting period of 6 months applies to the first scheme membership. All pre-existing medical conditions should be declared in the medical application form and is subject to medical undewriting Undeclared pre-existing conditions will not be covered during the policy period and will be underwritten at renewal.
A14: TPA | D14: NGI Healthnet
A15: Claims Settlement Basis (After application of Copayments) | B15: Within Provider Network | D15: Direct Billing Available. Reimbursement is also possible but will be settled at 80% of the usual & customary rates of the selected Network.
B16: Reimbursement Outside Network within the area of coverage | D16: Re-imbursement at 80% of actual costs (subject to be reasonable) or 80% of the usual & customary rates of the network, whichever is less.
A17: Life Threatening Emergency case within the area of coverage (to be notified within 24 hours of treatment if in a non-network provider) | D17: 100% of incurred costs
A18: Cover within the scope of territory, for Elective and Emergency | D18: When treatment received for emergency, accident or illnesses first arising after leaving U.A.E. whilst traveling on business or vacation for a maximum of 90 to 150 days within the geographical area, the country actual reasonable and customary prices will apply to inpatient and out -patient services.
A19: IN-PATIENT BENEFITS
A20: Room & Board | D20: Private | J20: =D20 -> Private
A21: Tests, diagnosis, treatments and surgeries for Non-urgent cases Pre-approval is required for this benefit. | D21: Covered
A22: Cash Indemnity for In-Patient hospitalizations that are not submitted to the Insurance Company | D22: =VLOOKUP($D$7,'TOB IN PUT'!$A$2:$S$17,11,0) -> Covered on Reimbursement up to AED 250 per night and a maximum of 10 nights. The Cash Indemnity claim must be submitted within 15 days after discharge from the hospital with a proof of hospitalization including a discharge summary.
A23: Parent Accommodation for child under 16 years of age | D23: =VLOOKUP($D$7,'TOB IN PUT'!$A$2:$S$17,6,0) -> Covered up to AED 300 / night
A24: The cost of accommodating a person accompanying an in-patient in the same room in cases of medical necessity at the recommendation of the treating doctor and after the prior approval of the insurance | D24: =VLOOKUP($D$7,'TOB IN PUT'!$A$2:$S$17,6,0) -> Covered up to AED 300 / night
A25: Emergency road ambulance services to and from hospital by registered ambulance services provider | D25: 100% Covered
A26: OUT-PATIENT BENEFITS
A27: Examination, diagnostic and treatment by authorized general practitioners, specialist, and consultants. (Will not be applicable for follow-up visits within 7 days from the same treatment and with the same doctor) | D27: =IF('Census List'!D35="Dubai",VLOOKUP('TOB '!$D$7,'TOB IN PUT'!A2:H11,8,0),VLOOKUP($D$7,'TOB IN PUT'!A12:H17,8,0)) -> 20% up to AED 50/- | J27: =F27 -> 0
A28: Laboratory tests carried out in authorized facility | D28: =VLOOKUP($D$7,'TOB IN PUT'!$A$2:$S$17,10,0) -> 100% Covered | J28: =D28 -> 100% Covered
A29: Radiology diagnostic services carried out in authorized facility. (Pre- approval required for Elective MRI, CT scans, Endoscopies) | D29: =VLOOKUP($D$7,'TOB IN PUT'!$A$2:$S$17,10,0) -> 100% Covered
A30: Physiotherapy Pre-approval is required for this benefit (as per policy conditions) | D30: =VLOOKUP($D$7,'TOB IN PUT'!$A$2:$S$17,12,0) -> 20 sessions per member per annum | J30: =D30 -> 20 sessions per member per annum
A31: Prescribed Drugs and Medicines | D31: =VLOOKUP($D$7,'TOB IN PUT'!$A$2:$S$17,9,0) -> Covered up to AED 10,000 with Nil Co Insurance (Branded) | J31: =D31 -> Covered up to AED 10,000 with Nil Co Insurance (Branded)
A32: PREVENTIVE SERVICES, VACCINES, AND IMMUNIZATIONS
A33: Essential vaccinations and inoculations | D33: =IF('Census List'!D35="Dubai"," Essential vaccinations and inoculations for newborns and children as stipulated in the DHAs policies and its updates in the assigned facilities (currently the same as Federal MOH) are covered ","Covered as per DOH list") -> Essential vaccinations and inoculations for newborns and children as stipulated in the DHAs policies and its updates in the assigned facilities (currently the same as Federal MOH) are covered
A34: Diabetes screening (Frequency restricted to: Diabetes: Every 3 years from age 30, High risk individuals annually from age 18) | D34: =IF('Census List'!D35="Dubai"," Covered as per terms, conditions and exclusions of the program defined by DHA ","Not Covered") -> Covered as per terms, conditions and exclusions of the program defined by DHA
A35: Adult Pneumococcal Conjugate Vaccine | D35: =IF('Census List'!D35="Dubai"," Covered as per terms, conditions and exclusions of the program defined by DHA ","Not Covered") -> Covered as per terms, conditions and exclusions of the program defined by DHA
A36: Influenza Vaccine | D36: =IF('Census List'!D35="Dubai","Covered once per annum“Limited to the cost of the vaccine and its administration only”","Not Covered") -> Covered once per annum“Limited to the cost of the vaccine and its administration only”
A37: Shingrix Vaccine (For NLSB members DXB visa holders) | D37: Covered only for members satisfying the eligibility criteria set by DHA. Limited to the cost of the vaccine and its administration only.
A38: ADDITIONAL BENEFITS
A39: Diagnostic and treatment services for dental and gum treatments (Emergency cases Only). Dental emergency is any injury to your teeth or gums that can put you at a risk of permanent damage, such as Chipped or broken teeth, Knocked-out tooth, Soft-tissue injuries etc. | D39: =IF('Census List'!D35="Dubai"," Subject to 20% coinsurance ","100% covered") -> Subject to 20% coinsurance
A40: Hearing and vision aids, and vision correction by surgeries and laser (Emergency cases Only) Hearing Emergencies include Object/insect in the ear, ruptured eardrum, sudden hearing loss etc. Vision Emergencies include bleeding or discharge from or around the eye, double vision, and Loss of vision, total or partial, one eye or both etc. | D40: =IF('Census List'!D35="Dubai"," Subject to 20% coinsurance ","100% covered") -> Subject to 20% coinsurance
A41: Cancer Screening & Treatment (Breast, Cervical & colorectal Covered under BASMAH patient support program .) | D41: =IF('Census List'!D35="Dubai"," Covered as per terms, conditions and exclusions of the program defined by DHA ","Not Covered") -> Covered as per terms, conditions and exclusions of the program defined by DHA
A42: Hepatitis B & C Virus (Screening and Treatment Screening, Healthcare Services, Investigations and Treatments only for members enrolled under Patient Support Program only) | D42: =IF('Census List'!D35="Dubai"," Covered as per terms, conditions and exclusions of the program defined by DHA ","Not Covered") -> Covered as per terms, conditions and exclusions of the program defined by DHA
...

Sheet HDF Review
B1: Group Name
B2: S. No. | C2: Member Name | D2: DOB DDMMYYYY | E2: Age | F2: Plan | G2: Network | H2: Height (cm) | I2: Weight (kg) | J2: BMI | K2: Base Premium | L2: Loadings | M2: Total Premium | N2: Observations | O2: Recommendations
B3: 1 | E3: =IF(D3="","",2021-YEAR(D3)) | J3: =IF(H3="","",IFERROR(I3/((H3/100)^2),0)) | M3: =IF(K3="","",(K3+(K3*L3)))
B4: 2 | E4: =IF(D4="","",2021-YEAR(D4)) | J4: =IF(H4="","",IFERROR(I4/((H4/100)^2),0)) | M4: =IF(K4="","",(K4+(K4*L4)))
B5: 3 | E5: =IF(D5="","",2021-YEAR(D5)) | J5: =IF(H5="","",IFERROR(I5/((H5/100)^2),0)) | M5: =IF(K5="","",(K5+(K5*L5)))
B6: 4 | E6: =IF(D6="","",2021-YEAR(D6)) | J6: =IF(H6="","",IFERROR(I6/((H6/100)^2),0)) | M6: =IF(K6="","",(K6+(K6*L6)))
B7: 5 | E7: =IF(D7="","",2020-YEAR(D7)) | J7: =IF(H7="","",IFERROR(I7/((H7/100)^2),0)) | M7: =IF(K7="","",(K7+(K7*L7)))
B8: 6 | E8: =IF(D8="","",2020-YEAR(D8)) | J8: =IF(H8="","",IFERROR(I8/((H8/100)^2),0)) | M8: =IF(K8="","",(K8+(K8*L8)))
B9: 7 | E9: =IF(D9="","",2020-YEAR(D9)) | J9: =IF(H9="","",IFERROR(I9/((H9/100)^2),0)) | M9: =IF(K9="","",(K9+(K9*L9)))
B10: 8 | E10: =IF(D10="","",2020-YEAR(D10)) | J10: =IF(H10="","",IFERROR(I10/((H10/100)^2),0)) | M10: =IF(K10="","",(K10+(K10*L10)))
B11: 9 | E11: =IF(D11="","",2020-YEAR(D11)) | J11: =IF(H11="","",IFERROR(I11/((H11/100)^2),0)) | M11: =IF(K11="","",(K11+(K11*L11)))
B12: 10 | E12: =IF(D12="","",2020-YEAR(D12)) | J12: =IF(H12="","",IFERROR(I12/((H12/100)^2),0)) | M12: =IF(K12="","",(K12+(K12*L12)))
B13: 11 | E13: =IF(D13="","",2020-YEAR(D13)) | J13: =IF(H13="","",IFERROR(I13/((H13/100)^2),0)) | M13: =IF(K13="","",(K13+(K13*L13)))
B14: 12 | E14: =IF(D14="","",2020-YEAR(D14)) | J14: =IF(H14="","",IFERROR(I14/((H14/100)^2),0)) | M14: =IF(K14="","",(K14+(K14*L14)))
B15: 13 | E15: =IF(D15="","",2020-YEAR(D15)) | J15: =IF(H15="","",IFERROR(I15/((H15/100)^2),0)) | M15: =IF(K15="","",(K15+(K15*L15)))
B16: 14 | E16: =IF(D16="","",2020-YEAR(D16)) | J16: =IF(H16="","",IFERROR(I16/((H16/100)^2),0)) | M16: =IF(K16="","",(K16+(K16*L16)))
B17: 15 | E17: =IF(D17="","",2020-YEAR(D17)) | J17: =IF(H17="","",IFERROR(I17/((H17/100)^2),0)) | M17: =IF(K17="","",(K17+(K17*L17)))
B18: 16 | E18: =IF(D18="","",2020-YEAR(D18)) | J18: =IF(H18="","",IFERROR(I18/((H18/100)^2),0)) | M18: =IF(K18="","",(K18+(K18*L18)))
... B32: 22 | E32: =IF(D32="","",2020-YEAR(D32)) | J32: =IF(H32="","",IFERROR(I32/((H32/100)^2),0)) | M32: =IF(K32="","",(K32+(K32*L32)))

Sheet Exclusions 
B1: Standard Policy Exclusions
B2: (Applicable to Dubai and Northern Emirates Visa holders)
B3: (Non Abu Dhabi Members)
A5: 1- | B5: Healthcare Services which are not medically necessary.
A6: 2- | B6: All expenses relating to dental prostheses, orthodontic treatments, etc.
A7: 3- | B7: Care for the sake of travelling.
A8: 4- | B8: Custodial care including
B9: (1 ) Non-medical treatment services.
B10: (2) Health-related services which do not seek to improve or which do not result in a change in the medical condition of the patient.
A11: 5- | B11: Services that do not require continuous administration by specialized medical personnel.
A12: 6- | B12: Personal comfort and convenience items (television, barber or beauty service, guest service and similar incidental services and supplies)
A13: 7- | B13: All cosmetic healthcare services and services associated with replacement of an existing breast implant. Cosmetic operations which are related to an Injury, sickness or congenital anomaly when the primary purpose is to improve physiological functioning of the involved part of the body and breast reconstruction following a mastectomy for cancer are covered.
A14: 8- | B14: Surgical and non-surgical treatment for obesity (including morbid obesity), and any other weight control programs, services, or supplies.
A15: 9- | B15: Medical services utilized for the sake of research, medically non-approved experiments, investigations, and pharmacological weight reduction regimens.
A16: 10- | B16: Healthcare Services that are not performed by Authorized Healthcare Service Providers.
A17: 11- | B17: Healthcare services and associated expenses for the treatment of alopecia, baldness, hair falling, dandruff or wigs.
A18: 12- | B18: Health services and supplies for smoking cessation programs and the treatment of nicotine addiction.
A19: 13- | B19: Treatment and services for contraception.
A20: 14- | B20: Treatment and services for sex transformation, sterilization or intended to correct a state of sterility or infertility or sexual dysfunction. Sterilization is allowed only if medically indicated and if allowed under the Law.
A21: 15- | B21: External prosthetic devices and medical equipment.
A22: 16- | B22: Treatments and services arising as a result of professional sports activities, including but not limited to, any form of aerial flight, any kind of power-vehicle race, water sports, horse riding activities, mountaineering activities, violent sports such as judo, boxing, and wrestling, bungee jumping and any other professional sports activities.
... A47: 41- | B47: Services and educational programs for people of determination, this also includes disability types such as but not limited to mental, intellectual, developmental, physical and/or psychological disabilities.
A49: Healthcare services outside the scope of health insurance (In Emergency cases as defined by PD 02-2017, the following must be covered until stabilization at minimum)
A50: 1 - | B50: Injuries or illnesses suffered by the Insured Person as a result of military operations of whatever type.
A51: 2 - | B51: Injuries or illnesses suffered by the Insured Person as a result of wars or acts of terror of whatever type.
A52: 3 - | B52: Healthcare services for injuries and accidents arising from nuclear or chemical contamination.
A53: 4 - | B53: Injuries resulting from natural disasters, including but not limited to: earthquakes, tornados and any other type of natural disaster.
A54: 5 - | B54: Injuries resulting from criminal acts or resisting authority by the Insured Person.
A55: 6 - | B55: Injuries resulting from a road traffic accident.
A56: 7 - | B56: Healthcare services for work related illnesses and injuries as per Federal Law No. 8 of 1980 concerning the Regulation of Work Relations, its amendments, and applicable laws in this respect.
A57: 8 - | B57: All cases resulting from the use of alcoholic drinks, controlled substances and drugs and hallucinating substances.
A58: 9 - | B58: Any investigation or treatment not prescribed by a doctor.
A59: 10 - | B59: Injuries resulting from attempted suicide or self-inflicted injuries.
A60: 11 - | B60: Diagnosis and treatment services for complications of exempted illnesses.
A61: 12 - | B61: All healthcare services for internationally and/or locally recognized epidemics.
A62: 13 - | B62: Healthcare services for patients suffering from (and related to the diagnosis and treatment of) HIV – AIDS and its complications and all types of hepatitis except virus A, B and C hepatitis.
A64: Standard Policy Exclusions (Valid for Abu Dhabi members only)
A65: 1 - | B65: Healthcare Services, which are not medically necessary.
A66: 2 - | B66: All expenses relating to dental treatment, dental prostheses, and orthodontic treatments.
A67: 3 - | B67: Domiciliary care; private nursing care; care for the sake of travelling.
...

Sheet TOB IN PUT
A1: Plan 1 | B1: Plan | C1: Aggregate Annual Limit | D1: Area of Coverage | E1: Medical Network | F1: Parent Accommodation for child under 18 years of age | G1: Home Nursing following inpatient treatment | H1: OP - Deductible | I1: OP Prescribed Drugs & Medicines | J1: OP Diagonistics | K1: Cash Indemnity for In-Patient hospitalizations that are not submitted to the Insurance Company | L1: Physiotherapy | M1: Repatriation of Mortal Remains | N1: Second Medical Opinion | O1: OUT -patient maternity | P1: In-patient maternity | Q1: Dental Benefit | R1: Alternative Medicines | S1: Psychiatric Treatment | T1: Newborn Entitlement | U1: Coverage
A2: Prime Plan-1 | B2: Prime Plan-1 | C2: AED 1,000,000 | D2: Worldwide | E2: HN Exclusive | F2: Covered to AED 450 / night | G2: Covered up to 13 weeks (on reimbusement) | H2: 20% up to AED 100/- | I2: Covered up to AED 15,000 with Nil Co Insurance (Branded) | J2: 100% Covered | K2: Covered on Reimbursement up to AED 300 per night and a maximum of 10 nights. The Cash Indemnity claim must be submitted within 15 days after discharge from the hospital with a proof of hospitalization including a discharge summary. | L2: 24 sessions per member per annum | M2: Covered up to Maximum AED. 20,000 per person per annum (Settled on Reimbursement basis with no co-pay) | N2: Covered | O2: Covered subject to Nil coinsurance payable by the insured maximum 15 visits are allowed (as per applicable network); Initial investigations to include: · FBC and Platelets · Blood group, Rhesus status and antibodies · VDRL · MSU & urinalysis· Rubella serology· HIV · Hep C offered to high risk patients · GTT if high risk · FBS , random s or A1c for all due to high prevalence of diabetes in UAE Visits to include reviews, checks and tests in accordance with DHA Antenatal Care Protocols 8 ante-natal ultrasound scans | P2: Covered with Nil co-insurance up payable by the insured) Normal Delivery: Aggregate Limit Per Year: AED.20,000 Medically necessary Cesarean Section, Complications & Medically Necessary Termination: Aggregate Limit Per Year: AED. 20,000/- (Where any condition develops which becomes life threatening to either the mother or the new born, the medically necessary expenses will be covered up to AED 150,000/-) | Q2: Covered up to AED 5,000/- with 20% Co Insurance | R2: Covered up to AED 2,500/- with 20% Co Insurance | S2: Covered up to AED 5,000/- with 20% Coins | T2: Coverage of a pregnant female is extended by the insurer to provide the same benefits for a newborn child of that female for a period up to 30 days from its date of birth. This cover is provided regardless of whether the newborn is eventually enrolled as a dependent member under the insurer’s policy. Covered under the mother’s card in event of Hospitalization, up to AED.150,000 PPPY | U2: Coverage of a pregnant female is extended by the insurer to provide the same benefits for a newborn child of that female for a period up to 30 days from its date of birth. This cover is provided regardless of whether the newborn is eventually enrolled as a dependent member under the insurer’s policy. Cover for 30 days from birth. BCG, Hepatitis B and neo-natal screening tests (Phenylketonuria (PKU), Congenital Hypothyroidism, sickle cell screening, congenital adrenal hyperplasia)
A3: Prime Plan-2 | B3: Prime Plan-2 | C3: AED 500,000 | D3: Worldwide | E3: HN Premier | F3: Covered to AED 400 / night | G3: Covered up to 13 weeks (on reimbusement) | H3: 20% up to AED 100/- | I3: Covered up to AED 15,000 with Nil Co Insurance (Branded) | J3: 100% Covered | K3: Covered on Reimbursement up to AED 300 per night and a maximum of 10 nights. The Cash Indemnity claim must be submitted within 15 days after discharge from the hospital with a proof of hospitalization including a discharge summary. | L3: 20 sessions per member per annum | M3: Covered up to Maximum AED. 20,000 per person per annum (Settled on Reimbursement basis with no co-pay) | N3: Covered | O3: Covered subject to Nil coinsurance payable by the insured maximum 15 visits are allowed (as per applicable network); Initial investigations to include: · FBC and Platelets · Blood group, Rhesus status and antibodies · VDRL · MSU & urinalysis· Rubella serology· HIV · Hep C offered to high risk patients · GTT if high risk · FBS , random s or A1c for all due to high prevalence of diabetes in UAE Visits to include reviews, checks and tests in accordance with DHA Antenatal Care Protocols 8 ante-natal ultrasound scans | P3: Covered with Nil co-insurance up payable by the insured) Normal Delivery: Aggregate Limit Per Year: AED.18,000 Medically necessary Cesarean Section, Complications & Medically Necessary Termination: Aggregate Limit Per Year: AED. 18,000 (Where any condition develops which becomes life threatening to either the mother or the new born, the medically necessary expenses will be covered up to AED 150,000/-) | Q3: Covered up to AED 3,500/- with 20% Co Insurance | R3: Covered up to AED 2,500/- with 20% Co Insurance | S3: Covered up to AED 5,000/- with 20% Coins | T3: Coverage of a pregnant female is extended by the insurer to provide the same benefits for a newborn child of that female for a period up to 30 days from its date of birth. This cover is provided regardless of whether the newborn is eventually enrolled as a dependent member under the insurer’s policy. Covered under the mother’s card in event of Hospitalization, up to AED.150,000 PPPY | U3: Coverage of a pregnant female is extended by the insurer to provide the same benefits for a newborn child of that female for a period up to 30 days from its date of birth. This cover is provided regardless of whether the newborn is eventually enrolled as a dependent member under the insurer’s policy. Cover for 30 days from birth. BCG, Hepatitis B and neo-natal screening tests (Phenylketonuria (PKU), Congenital Hypothyroidism, sickle cell screening, congenital adrenal hyperplasia)
A4: Classic Plan-1 | B4: Calssic Plan-1 | C4: AED 300,000 | D4: Worldwide Excluding USA and Canada | E4: HN Advantage (Additional 10% Co-pay applicable on all OP Services excluding Pharmacy at NMC Royal Hosp. Sharjah) | F4: Covered up to AED 350 / night | G4: Covered up to 10 weeks (on reimbusement) | H4: 20% up to AED 50/- | I4: Covered up to AED 10,000 with Nil Co Insurance (Branded) | J4: 100% Covered | K4: Covered on Reimbursement up to AED 300 per night and a maximum of 10 nights. The Cash Indemnity claim must be submitted within 15 days after discharge from the hospital with a proof of hospitalization including a discharge summary. | L4: 20 sessions per member per annum | M4: Covered up to Maximum AED. 15,000 per person per annum (Settled on Reimbursement basis with no co-pay) | N4: Covered | O4: Covered subject to Nil coinsurance payable by the insured maximum 12 visits are allowed (as per applicable network); Initial investigations to include: · FBC and Platelets · Blood group, Rhesus status and antibodies · VDRL · MSU & urinalysis· Rubella serology· HIV · Hep C offered to high risk patients · GTT if high risk · FBS , random s or A1c for all due to high prevalence of diabetes in UAE Visits to include reviews, checks and tests in accordance with DHA Antenatal Care Protocols 8 ante-natal ultrasound scans | P4: Covered with Nil co-insurance up payable by the insured) Normal Delivery: Aggregate Limit Per Year: AED.15,000 Medically necessary Cesarean Section, Complications & Medically Necessary Termination: Aggregate Limit Per Year: AED. 15,000/- (Where any condition develops which becomes life threatening to either the mother or the new born, the medically necessary expenses will be covered up to AED 150,000/-) | Q4: Covered up to AED 2,500/- with 20% Co Insurance | R4: Covered up to AED 2,000/- with 20% Co Insurance | S4: Covered up to AED 3,000/- with 20% Coins | T4: Coverage of a pregnant female is extended by the insurer to provide the same benefits for a newborn child of that female for a period up to 30 days from its date of birth. This cover is provided regardless of whether the newborn is eventually enrolled as a dependent member under the insurer’s policy. Covered under the mother’s card in event of Hospitalization, up to AED.150,000 PPPY | U4: Coverage of a pregnant female is extended by the insurer to provide the same benefits for a newborn child of that female for a period up to 30 days from its date of birth. This cover is provided regardless of whether the newborn is eventually enrolled as a dependent member under the insurer’s policy. Cover for 30 days from birth. BCG, Hepatitis B and neo-natal screening tests (Phenylketonuria (PKU), Congenital Hypothyroidism, sickle cell screening, congenital adrenal hyperplasia)
